Traceback (most recent call last):
  File "C:\Users\budde\anaconda3\envs\py37\lib\site-packages\jupyter_cache\executors\utils.py", line 56, in single_nb_execution
    record_timing=False,
  File "C:\Users\budde\anaconda3\envs\py37\lib\site-packages\nbclient\client.py", line 1093, in execute
    return NotebookClient(nb=nb, resources=resources, km=km, **kwargs).execute()
  File "C:\Users\budde\anaconda3\envs\py37\lib\site-packages\nbclient\util.py", line 84, in wrapped
    return just_run(coro(*args, **kwargs))
  File "C:\Users\budde\anaconda3\envs\py37\lib\site-packages\nbclient\util.py", line 62, in just_run
    return loop.run_until_complete(coro)
  File "C:\Users\budde\anaconda3\envs\py37\lib\asyncio\base_events.py", line 587, in run_until_complete
    return future.result()
  File "C:\Users\budde\anaconda3\envs\py37\lib\site-packages\nbclient\client.py", line 560, in async_execute
    cell, index, execution_count=self.code_cells_executed + 1
  File "C:\Users\budde\anaconda3\envs\py37\lib\site-packages\nbclient\client.py", line 854, in async_execute_cell
    self._check_raise_for_error(cell, exec_reply)
  File "C:\Users\budde\anaconda3\envs\py37\lib\site-packages\nbclient\client.py", line 756, in _check_raise_for_error
    raise CellExecutionError.from_cell_and_msg(cell, exec_reply_content)
nbclient.exceptions.CellExecutionError: An error occurred while executing the following cell:
------------------
import stata_setup
stata_setup.config("C:/Program Files/Stata17", "se")
------------------

[1;31m---------------------------------------------------------------------------[0m
[1;31mModuleNotFoundError[0m                       Traceback (most recent call last)
[1;32m~\AppData\Local\Temp/ipykernel_20188/571653080.py[0m in [0;36m<module>[1;34m[0m
[1;32m----> 1[1;33m [1;32mimport[0m [0mstata_setup[0m[1;33m[0m[1;33m[0m[0m
[0m[0;32m      2[0m [0mstata_setup[0m[1;33m.[0m[0mconfig[0m[1;33m([0m[1;34m"C:/Program Files/Stata17"[0m[1;33m,[0m [1;34m"se"[0m[1;33m)[0m[1;33m[0m[1;33m[0m[0m

[1;31mModuleNotFoundError[0m: No module named 'stata_setup'
ModuleNotFoundError: No module named 'stata_setup'

